Workbook

Sheet Laporan orbits
A3: No | B3: Tanggal | C3: Admin | D3: Deskripsi | G3: Keterangan
D4: Nama Clien | E4: Instansi | F4: Keperluan
A5: 1. | B5: 45692 | C5: Sofi, Anysa, Aini | D5: Andrian (tim kak Yasmin) | E5: PT.SEPCO | F5: Sewa private room (block office) selama 3 bulan | G5: Lunas (tf ke ibu an atas nama Media Wedia)
A6: 2. | B6: 45693 | C6: Dhea, Enchy | D6: Mas Dandy | E6: Cafe Sanama | F6: Interview | G6: Konfirmasi lewat bu an
A7: 3. | B7: 45694 | C7: Sofi, Anysa, Aini | D7: Mas Dandy | E7: Cafe Sanama | F7: Survei lokasi, dan penataan ruang, ukur ruangan | G7: Ukur ruangan
A8: 4. | B8: 45694 | C8: Sofi, Anysa, Aini | D8: Mas Addrian | E8: PT.SEPCO | F8: Meeting Privat Room Virtual Office 5 orang | G8: Sudah konfirmasi ke Ibu Ann (pembayaran VO)
A9: 5. | B9: 45695 | C9: Dhea, Enchy | D9: Mas Dandy | E9: Cafe Sanama | F9: Bertemu Bu An | G9: -
A10: 6.

Sheet Laporan sanama februari
D1: 21 hari
B3: No | C3: Hari/ Tanggal | D3: List menu | E3: Jumlah | F3: Harga | G3: Total | H3: Refund | I3: Pemasukan | J3: Total Menu Terjual | O3: menu utama | P3: 1000 | X3: LAPORAN PER 5 HARI
B4: 1. | C4: 45696 | D4: D012 | E4: 6 | F4: 15000 | G4: =E4*F4 -> 90000 | I4: =E4-H4 -> 6 | J4: =SUM(E4:E12) -> 20 | O4: ekstra | P4: 500 | R4: Tgl | S4: Menu Utama | T4: Ekstra | U4: Total
D5: D006 | E5: 3 | F5: 15000 | G5: =E5*F5 -> 45000 | I5: =E5-H5 -> 3 | R5: 08/09-02-2025 | S5: =P3*J4 -> 20000 | U5: =sum(S5:T5) -> 20000 | V5: =U5 -> 20000 | X5: 08-12 februari 2025 | Y5: =sum(U5:U8) -> 71500
D6: AYM SE | E6: 2 | F6: 15000 | G6: =E6*F6 -> 30000 | I6: =E6-H6 -> 2 | R6: 45698 | S6: =P3*J13 -> 28000 | T6: =P4*O13 -> 500 | U6: =sum(S6:T6) -> 28500 | V6: =V5+U6 -> 48500 | X6: 13-17 februari 2025 | Y6: =SUM(U9:U13) -> 80500
D7: VANILA01 | E7: 2 | F7: 13000 | G7: =E7*F7 -> 26000 | I7: =E7-H7 -> 2 | O7: REFUND | P7: =SUM(H4:H232) -> 0 | R7: 45699 | S7: =P3*J24 -> 12000 | T7: =P4*O24 -> 1500 | U7: =sum(S7:T7) -> 13500 | V7: =V6+U7 -> 62000 | X7: 18-22 februari 2025 | Y7: =SUM(U14:U22) -> 365000
D8: MTG AYM | E8: 2 | F8: 15000 | G8: =E8*F8 -> 30000 | I8: =E8-H8 -> 2 | R8: 45700 | S8: =P3*J30 -> 9000 | T8: =P4*O30 -> 500 | U8: =sum(S8:T8) -> 9500 | V8: =V7+U8 -> 71500 | X8: 23-27 februari 2025 | Y8: =sum(U19:U23) -> 228000
B9: 2. | C9: 45697 | D9: SMBL M | E9: 2 | F9: 15000 | G9: =E9*F9 -> 30000 | I9: =E9-H9 -> 2 | R9: 45701 | S9: =P3*J36 -> 7000 | T9: =P4*O36 -> 1000 | U9: =sum(S9:T9) -> 8000 | V9: =V8+U9 -> 79500 | X9: 45716 | Y9: =U24 -> 45000
D10: bangladehs | E10: 1 | F10: 13000 | G10: =E10*F10 -> 13000 | I10: =E10-H10 -> 1 | R10: 45702 | S10: =P3*J39 -> 14000 | T10: =P4*O39 -> 1000 | U10: =sum(S10:T10) -> 15000 | V10: =V9+U10 -> 94500
D11: D018 | E11: 1 | F11: 13000 | G11: =E11*F11 -> 13000 | I11: =E11-H11 -> 1 | R11: 45703 | S11: =P3*J45 -> 9000 | T11: =P4*O45 -> 500 | U11: =sum(S11:T11) -> 9500 | V11: =V10+U11 -> 104000
D12: AIR01 | E12: 1 | F12: 5000 | G12: =E12*F12 -> 5000 | I12: =E12-H12 -> 1 | R12: 45704 | S12: =P3*J52 -> 37000 | T12: =P4*O52 -> 1500 | U12: =sum(S12:T12) -> 38500 | V12: =V11+U12 -> 142500
B13: 3. | C13: 45698 | D13: AYM SE | E13: 6 | F13: 15000 | G13: =E13*F13 -> 90000 | I13: =E13-H13 -> 6 | J13: =SUM(E13:E23) -> 28 | K13: Event008 | L13: 1 | M13: 5000 | N13: =L13*M13 -> 5000 | O13: =L13 -> 1 | R13: 45705 | S13: =P3*J69 -> 9000 | T13: =P4*O69 -> 500 | U13: =sum(S13:T13) -> 9500 | V13: =V12+U13 -> 152000
D14: Event0021 | E14: 5 | F14: 10000 | G14: =E14*F14 -> 50000 | I14: =E14-H14 -> 5 | R14: 45706 | S14: =P3*J75 -> 34000 | U14: =sum(S14:T14) -> 34000 | V14: =V13+U14 -> 186000 | X14: Total keselutuhan | Y14: =sum(Y5:Y9) -> 790000
D15: MTG AYM | E15: 4 | F15: 15000 | G15: =E15*F15 -> 60000 | I15: =E15-H15 -> 4 | R15: 45707 | S15: =P3*J91 -> 29000 | U15: =sum(S15:T15) -> 29000 | V15: =V14+U15 -> 215000
D16: AIR01 | E16: 3 | F16: 5000 | G16: =E16*F16 -> 15000 | I16: =E16-H16 -> 3 | R16: 45708 | S16: =P3*J100 -> 52000 | U16: =SUM(S16:T16) -> 52000 | V16: =V15+U16 -> 267000
D17: SMBL M | E17: 2 | F17: 15000 | G17: =E17*F17 -> 30000 | I17: =E17-H17 -> 2 | R17: 45709 | S17: =P3*J115 -> 65000 | U17: =SUM(S17:T17) -> 65000 | V17: =V16+U17 -> 332000
D18: AYM006 | E18: 2 | F18: 18000 | G18: =E18*F18 -> 36000 | I18: =E18-H18 -> 2 | R18: 45710 | S18: =P3*J134 -> 28000 | T18: =P4*O134 -> 500 | U18: =SUM(S18:T18) -> 28500 | V18: =V17+U18 -> 360500
D19: D018 | E19: 2 | F19: 13000 | G19: =E19*F19 -> 26000 | I19: =E19-H19 -> 2 | R19: 45711 | S19: =P3*J148 -> 27000 | U19: =SUM(S19:T19) -> 27000 | V19: =V18+U19 -> 387500
D20: D012 | E20: 1 | F20: 15000 | G20: =E20*F20 -> 15000 | I20: =E20-H20 -> 1 | R20: 45712 | S20: =P3*J163 -> 51000 | T20: =P4*O163 -> 1000 | U20: =SUM(S20:T20) -> 52000 | V20: =V19+U20 -> 439500
D21: D006 | E21: 1 | F21: 15000 | G21: =E21*F21 -> 15000 | I21: =E21-H21 -> 1 | R21: 45713 | S21: =P3*J176 -> 25000 | U21: =SUM(S21:T21) -> 25000 | V21: =V20+U21 -> 464500
D22: LEMONTEA | E22: 1 | F22: 13000 | G22: =E22*F22 -> 13000 | I22: =E22-H22 -> 1 | R22: 45714 | S22: =P3*J186 -> 52000 | T22: =P4*O186 -> 500 | U22: =SUM(S22:T22) -> 52500 | V22: =V21+U22 -> 517000
D23: D009 | E23: 1 | F23: 15000 | G23: =E23*F23 -> 15000 | I23: =E23-H23 -> 1 | R23: 45715 | S23: =P3*J202 -> 71000 | T23: =P4*O202 -> 500 | U23: =SUM(S23:T23) -> 71500 | V23: =V22+U23 -> 588500
B24: 4. | C24: 45699 | D24: AYM006 | E24: 4 | F24: 18000 | G24: =E24*F24 -> 72000 | I24: =E24-H24 -> 4 | J24: =SUM(I24:I29) -> 12 | K24: Event008 | L24: 3 | M24: 5000 | N24: =L24*M24 -> 15000 | O24: =L24 -> 3 | R24: 45716 | S24: =P3*J219 -> 45000 | U24: =SUM(S24:T24) -> 45000 | V24: =V23+U24 -> 633500
D25: AYM SE | E25: 3 | F25: 15000 | G25: =E25*F25 -> 45000 | I25: =E25-H25 -> 3
D26: AIR01 | E26: 2 | F26: 5000 | G26: =E26*F26 -> 10000 | I26: =E26-H26 -> 2
D27: D018 | E27: 1 | F27: 13000 | G27: =E27*F27 -> 13000 | I27: =E27-H27 -> 1
D28: MTG AYM | E28: 1 | F28: 15000 | G28: =E28*F28 -> 15000 | I28: =E28-H28 -> 1
D29: VANILA01 | E29: 1 | F29: 13000 | G29: =E29*F29 -> 13000 | I29: =E29-H29 -> 1
B30: 5. | C30: 45700 | D30: AYAM SE | E30: 2 | F30: 15000 | G30: =E30*F30 -> 30000 | I30: =E30-H30 -> 2 | J30: =SUM(I30:I35) -> 9 | K30: DGN 1 | L30: 1 | M30: 8000 | N30: =M30*L30 -> 8000 | O30: =L30 -> 1
D31: AYAM006 | E31: 2 | F31: 18000 | G31: =E31*F31 -> 36000 | I31: =E31-H31 -> 2
D32: AIR01 | E32: 2 | F32: 5000 | G32: =E32*F32 -> 10000 | I32: =E32-H32 -> 2
D33: MTG AYM | E33: 1 | F33: 15000 | G33: =E33*F33 -> 15000 | I33: =E33-H33 -> 1
D34: 0002 | E34: 1 | F34: 18000 | G34: =E34*F34 -> 18000 | I34: =E34-H34 -> 1
D35: D009 | E35: 1 | F35: 15000 | G35: =E35*F35 -> 15000 | I35: =E35-H35 -> 1
B36: 6. | C36: 45701 | D36: AYAM006 | E36: 4 | F36: 18000 | G36: =E36*F36 -> 72000 | I36: =E36-H36 -> 4 | J36: =SUM(I36:I38) -> 7 | K36: EVENT008 | L36: 2 | M36: 5000 | N36: =M36*L36 -> 10000 | O36: =L36 -> 2
D37: D009 | E37: 2 | F37: 15000 | G37: =E37*F37 -> 30000 | I37: =E37-H37 -> 2
D38: AIR01 | E38: 1 | F38: 5000 | G38: =E38*F38 -> 5000 | I38: =E38-H38 -> 1
B39: 7. | C39: 45702 | D39: AYM006 | E39: 4 | F39: 18000 | G39: =E39*F39 -> 72000 | I39: =E39-H39 -> 4 | J39: =SUM(I39:I44) -> 14 | K39: EVENT008 | L39: 2 | M39: 5000 | N39: =M39*L39 -> 10000 | O39: =L39 -> 2
D40: D004 | E40: 3 | F40: 12000 | G40: =E40*F40 -> 36000 | I40: =E40-H40 -> 3
D41: LEMONTEA | E41: 2 | F41: 13000 | G41: =E41*F41 -> 26000 | I41: =E41-H41 -> 2
...

Sheet laporan sanama maret
K1: 25 hari
B2: No | C2: Hari/ Tanggal | D2: List menu | E2: Jumlah | F2: Harga | G2: Total | H2: Refund | I2: Pemasukan | J2: Total Menu Terjual
B3: 1. | C3: 45717 | D3: AYM006 | E3: 8 | F3: 18000 | G3: =E3*F3 -> 144000 | I3: =E3-H3 -> 8 | J3: =SUM(I3:I17) -> 43 | Q3: menu utama | R3: 1000 | Y3: LAPORAN PER 5 HARI
D4: AIR01 | E4: 7 | F4: 5000 | G4: =E4*F4 -> 35000 | I4: =E4-H4 -> 7 | Q4: ekstra | R4: 500 | T4: Tgl | U4: Menu Utama | V4: Ekstra | W4: Total | Y4: 01-05 Maret 2025 | Z4: =sum(W5:W9) -> 350500
D5: MTG AYM | E5: 6 | F5: 15000 | G5: =E5*F5 -> 90000 | I5: =E5-H5 -> 6 | T5: 45717 | U5: ='Laporan sanama februari'!P3*'laporan sanama maret'!J3 -> 43000 | V5: ='Laporan sanama februari'!P4*'laporan sanama maret'!O10 -> 500 | W5: =SUM(U5:V5) -> 43500 | Y5: 06-10 Maret 2025 | Z5: =SUM(W10:W14) -> 657000
D6: TBK22 | E6: 4 | F6: 10000 | G6: =E6*F6 -> 40000 | I6: =E6-H6 -> 4 | T6: 45718 | U6: ='Laporan sanama februari'!P3*'laporan sanama maret'!J18 -> 49000 | V6: ='Laporan sanama februari'!P4*'laporan sanama maret'!O26 -> 1000 | W6: =SUM(U6:V6) -> 50000 | Y6: 11-15 Maret 2025 | Z6: =SUM(W15:W19) -> 589000
D7: NSAYAM005 | E7: 4 | F7: 15000 | G7: =E7*F7 -> 60000 | I7: =E7-H7 -> 4 | Q7: REFUND | R7: =SUM(H3:H386) -> 0 | T7: 45719 | U7: ='Laporan sanama februari'!P3*'laporan sanama maret'!J36 -> 55000 | W7: =SUM(U7:V7) -> 55000 | Y7: 16-20 Maret 2025 | Z7: =sum(W20:W24) -> 627000
D8: D002 | E8: 3 | F8: 13000 | G8: =E8*F8 -> 39000 | I8: =E8-H8 -> 3 | T8: 45720 | U8: =R3*J58 -> 113000 | W8: =SUM(U8:V8) -> 113000 | Y8: 21-26 Maret 2025 | Z8: =sum(W25:W29) -> 214000
D9: bangladehs | E9: 2 | F9: 13000 | G9: =E9*F9 -> 26000 | I9: =E9-H9 -> 2 | T9: 45721 | U9: =R3*J78 -> 89000 | W9: =SUM(U9:V9) -> 89000
D10: D012 | E10: 2 | F10: 15000 | G10: =E10*F10 -> 30000 | I10: =E10-H10 -> 2 | K10: DGN1 | L10: 1 | M10: 8000 | N10: =M10*L10 -> 8000 | O10: =L10 -> 1 | T10: 45722 | U10: =R3*J95 -> 107000 | W10: =SUM(U10:V10) -> 107000
D11: D006 | E11: 1 | F11: 15000 | G11: =E11*F11 -> 15000 | I11: =E11-H11 -> 1 | T11: 45723 | U11: =R3*J111 -> 125000 | W11: =SUM(U11:V11) -> 125000
D12: D004 | E12: 1 | F12: 18000 | G12: =E12*F12 -> 18000 | I12: =E12-H12 -> 1 | T12: 45724 | U12: =R3*J128 -> 135000 | W12: =SUM(U12:V12) -> 135000
D13: D018 | E13: 1 | F13: 13000 | G13: =E13*F13 -> 13000 | I13: =E13-H13 -> 1 | T13: 45725 | U13: =R3*J146 -> 135000 | W13: =SUM(U13:V13) -> 135000 | Y13: Total keseluruhan | Z13: =sum(Z4:Z8) -> 2437500
D14: VANILA01 | E14: 1 | F14: 13000 | G14: =E14*F14 -> 13000 | I14: =E14-H14 -> 1 | T14: 45726 | U14: =R3*J164 -> 155000 | W14: =SUM(U14:V14) -> 155000
D15: 0000 | E15: 1 | F15: 18000 | G15: =E15*F15 -> 18000 | I15: =E15-H15 -> 1 | T15: 45727 | U15: =R3*J180 -> 122000 | W15: =SUM(U15:V15) -> 122000
D16: Event0021 | E16: 1 | F16: 10000 | G16: =E16*F16 -> 10000 | I16: =E16-H16 -> 1 | T16: 45728 | U16: =R3*J192 -> 135000 | W16: =SUM(U16:V16) -> 135000
D17: SMBL M | E17: 1 | F17: 15000 | G17: =E17*F17 -> 15000 | I17: =E17-H17 -> 1 | T17: 45729 | U17: =R3*J209 -> 128000 | W17: =SUM(U17:V17) -> 128000
B18: 2. | C18: 45718 | D18: D002 | E18: 10 | F18: 13000 | G18: =E18*F18 -> 130000 | I18: =E18-H18 -> 10 | J18: =SUM(I18:I35) -> 49 | T18: 45730 | U18: =R3*J227 -> 100000 | W18: =SUM(U18:V18) -> 100000
D19: AYM006 | E19: 6 | F19: 18000 | G19: =E19*F19 -> 108000 | I19: =E19-H19 -> 6 | T19: 45731 | U19: =R3*J242 -> 104000 | W19: =SUM(U19:V19) -> 104000
D20: INDOMIE01 | E20: 4 | F20: 10000 | G20: =E20*F20 -> 40000 | I20: =E20-H20 -> 4 | T20: 45732 | U20: =R3*J257 -> 114000 | W20: =SUM(U20:V20) -> 114000
D21: NSAYAM005 | E21: 3 | F21: 15000 | G21: =E21*F21 -> 45000 | I21: =E21-H21 -> 3 | T21: 45733 | U21: =R3*J272 -> 115000 | W21: =SUM(U21:V21) -> 115000
D22: TBK22 | E22: 3 | F22: 10000 | G22: =E22*F22 -> 30000 | I22: =E22-H22 -> 3 | T22: 45734 | U22: =R3*J287 -> 166000 | W22: =SUM(U22:V22) -> 166000
D23: AYM SE | E23: 3 | F23: 15000 | G23: =E23*F23 -> 45000 | I23: =E23-H23 -> 3 | T23: 45735 | U23: =R3*J300 -> 120000 | W23: =SUM(U23:V23) -> 120000
D24: Event0021 | E24: 2 | F24: 10000 | G24: =E24*F24 -> 20000 | I24: =E24-H24 -> 2 | T24: 45736 | U24: =R3*J315 -> 112000 | W24: =SUM(U24:V24) -> 112000
D25: MTG AYM | E25: 2 | F25: 15000 | G25: =E25*F25 -> 30000 | I25: =E25-H25 -> 2 | T25: 45737 | U25: =R3*J332 -> 118000 | W25: =SUM(U25:V25) -> 118000
D26: SMBL M | E26: 2 | F26: 15000 | G26: =E26*F26 -> 30000 | I26: =E26-H26 -> 2 | K26: EKS002 | L26: 2 | M26: 8000 | N26: =M26*L26 -> 16000 | O26: =L26 -> 2 | T26: 45739 | U26: =R3*J346 -> 25000 | W26: =SUM(U26:V26) -> 25000
D27: bangladehs | E27: 2 | F27: 13000 | G27: =E27*F27 -> 26000 | I27: =E27-H27 -> 2 | T27: 45740 | U27: =R3*J357 -> 29000 | W27: =SUM(U27:V27) -> 29000
D28: VANILA01 | E28: 2 | F28: 13000 | G28: =E28*F28 -> 26000 | I28: =E28-H28 -> 2 | T28: 45741 | U28: =R3*J369 -> 29000 | W28: =SUM(U28:V28) -> 29000
D29: AIR01 | E29: 2 | F29: 5000 | G29: =E29*F29 -> 10000 | I29: =E29-H29 -> 2 | T29: 45742 | U29: =R3*J379 -> 13000 | W29: =SUM(U29:V29) -> 13000
D30: 0001 | E30: 2 | F30: 18000 | G30: =E30*F30 -> 36000 | I30: =E30-H30 -> 2
D31: 0002 | E31: 2 | F31: 18000 | G31: =E31*F31 -> 36000 | I31: =E31-H31 -> 2
D32: D004 | E32: 1 | F32: 18000 | G32: =E32*F32 -> 18000 | I32: =E32-H32 -> 1
D33: D006 | E33: 1 | F33: 15000 | G33: =E33*F33 -> 15000 | I33: =E33-H33 -> 1
D34: D012 | E34: 1 | F34: 15000 | G34: =E34*F34 -> 15000 | I34: =E34-H34 -> 1
D35: D009 | E35: 1 | F35: 15000 | G35: =E35*F35 -> 15000 | I35: =E35-H35 -> 1
B36: 3. | C36: 45719 | D36: Event0021 | E36: 9 | F36: 10000 | G36: =E36*F36 -> 90000 | I36: =E36-H36 -> 9 | J36: =sum(I36:I57) -> 55
D37: AYM006 | E37: 8 | F37: 18000 | G37: =E37*F37 -> 144000 | I37: =E37-H37 -> 8
D38: D002 | E38: 8 | F38: 13000 | G38: =E38*F38 -> 104000 | I38: =E38-H38 -> 8
D39: MTG AYM | E39: 5 | F39: 15000 | G39: =E39*F39 -> 75000 | I39: =E39-H39 -> 5
D40: AIR01 | E40: 3 | F40: 5000 | G40: =E40*F40 -> 15000 | I40: =E40-H40 -> 3
...

Sheet laporan sanama april
D1: 28 hari
L2: menu utama | M2: 1000
B3: No | C3: Hari/ Tanggal | D3: List menu | E3: Jumlah | F3: Harga | G3: Total | H3: Refund | I3: Pemasukan | J3: Total Menu Terjual | L3: ekstra | M3: 500 | O3: Tgl | P3: Menu Utama | Q3: Ekstra | R3: Total | T3: Laporan per 1 Minggu
B4: 1. | C4: 03 - 06, April 2025 | D4: AYM006 | E4: 15 | F4: 18000 | G4: =E4*F4 -> 270000 | I4: =E4-H4 -> 15 | J4: =SUM(I4:I16) -> 47 | O4: 03-09 April 2025 | P4: =J4*M2 -> 47000 | R4: =SUM(P4:Q4) -> 47000 | T4: 03 - 09 April 2025 | U4: =sum(R4:R5) -> 213000
D5: VANILA01 | E5: 6 | F5: 13000 | G5: =E5*F5 -> 78000 | I5: =E5-H5 -> 6 | O5: 07-09 April 2025 | P5: =M2*J17 -> 166000 | R5: =SUM(P5:Q5) -> 166000 | T5: 10 - 16 April 2025 | U5: =sum(R6:R7) -> 386000
D6: MTG AYM | E6: 5 | F6: 15000 | G6: =E6*F6 -> 75000 | I6: =E6-H6 -> 5 | O6: 10-13 April 2025 | P6: =M2*J36 -> 204000 | R6: =SUM(P6:Q6) -> 204000 | T6: 17 - 23 April 2025 | U6: =sum(R8:R9) -> 420000
D7: AYM SE | E7: 4 | F7: 15000 | G7: =E7*F7 -> 60000 | I7: =E7-H7 -> 4 | O7: 14-16 April 2025 | P7: =M2*J55 -> 182000 | R7: =SUM(P7:Q7) -> 182000 | T7: 24 - 26 April 2025 | U7: =R10 -> 173000
D8: SMBL M | E8: 3 | F8: 15000 | G8: =E8*F8 -> 45000 | I8: =E8-H8 -> 3 | O8: 17-20 April 2025 | P8: =M2*J77 -> 250000 | R8: =SUM(P8:Q8) -> 250000
D9: LEMONTEA | E9: 3 | F9: 13000 | G9: =E9*F9 -> 39000 | I9: =E9-H9 -> 3 | O9: 21-23 April 2025 | P9: =M2*J99 -> 170000 | R9: =SUM(P9:Q9) -> 170000
D10: D006 | E10: 2 | F10: 15000 | G10: =E10*F10 -> 30000 | I10: =E10-H10 -> 2 | O10: 24-26 April 2025 | P10: =M2*J119 -> 173000 | R10: =SUM(P10:Q10) -> 173000
D11: 1 | E11: 2 | F11: 18000 | G11: =E11*F11 -> 36000 | I11: =E11-H11 -> 2
D12: NSAYAM005 | E12: 2 | F12: 15000 | G12: =E12*F12 -> 30000 | I12: =E12-H12 -> 2
D13: DG01 | E13: 2 | F13: 18000 | G13: =E13*F13 -> 36000 | I13: =E13-H13 -> 2
D14: D004 | E14: 1 | F14: 18000 | G14: =E14*F14 -> 18000 | I14: =E14-H14 -> 1
D15: Event21 | E15: 1 | F15: 10000 | G15: =E15*F15 -> 10000 | I15: =E15-H15 -> 1
D16: bangladehs | E16: 1 | F16: 13000 | G16: =E16*F16 -> 13000 | I16: =E16-H16 -> 1
B17: 2. | C17: 07 - 09 April 2025 | D17: AYM SE | E17: 22 | F17: 15000 | G17: =E17*F17 -> 330000 | I17: =E17-H17 -> 22 | J17: =sum(I17:I35) -> 166 | O17: Total Keseluruhan | P17: =sum(U4:U7) -> 1192000
D18: AYM006 | E18: 22 | F18: 18000 | G18: =E18*F18 -> 396000 | I18: =E18-H18 -> 22
D19: MTG AYM | E19: 17 | F19: 15000 | G19: =E19*F19 -> 255000 | I19: =E19-H19 -> 17
D20: NSAYAM005 | E20: 16 | F20: 15000 | G20: =E20*F20 -> 240000 | I20: =E20-H20 -> 16
D21: D002 | E21: 12 | F21: 13000 | G21: =E21*F21 -> 156000 | I21: =E21-H21 -> 12
D22: DMS001 | E22: 11 | F22: 15000 | G22: =E22*F22 -> 165000 | I22: =E22-H22 -> 11
D23: D018 | E23: 11 | F23: 13000 | G23: =E23*F23 -> 143000 | I23: =E23-H23 -> 11
D24: VANILA01 | E24: 9 | F24: 13000 | G24: =E24*F24 -> 117000 | I24: =E24-H24 -> 9
D25: Event21 | E25: 7 | F25: 10000 | G25: =E25*F25 -> 70000 | I25: =E25-H25 -> 7
D26: D006 | E26: 6 | F26: 15000 | G26: =E26*F26 -> 90000 | I26: =E26-H26 -> 6
D27: DMS002 | E27: 6 | F27: 25000 | G27: =E27*F27 -> 150000 | I27: =E27-H27 -> 6
D28: SMBL M | E28: 5 | F28: 15000 | G28: =E28*F28 -> 75000 | I28: =E28-H28 -> 5
D29: D009 | E29: 4 | F29: 15000 | G29: =E29*F29 -> 60000 | I29: =E29-H29 -> 4
... D35: DMS003 | E35: 2 | F35: 35000 | G35: =E35*F35 -> 70000 | I35: =E35-H35 -> 2
B36: 3. | C36: 10 - 13 April 2025 | D36: AYM006 | E36: 47 | F36: 18000 | G36: =E36*F36 -> 846000 | I36: =E36-H36 -> 47 | J36: =sum(I36:I54) -> 204
D37: MTG AYM | E37: 25 | F37: 15000 | G37: =E37*F37 -> 375000 | I37: =E37-H37 -> 25
D38: Event21 | E38: 25 | F38: 10000 | G38: =E38*F38 -> 250000 | I38: =E38-H38 -> 25
D39: AYM SE | E39: 18 | F39: 15000 | G39: =E39*F39 -> 270000 | I39: =E39-H39 -> 18
D40: NSAYAM005 | E40: 15 | F40: 15000 | G40: =E40*F40 -> 225000 | I40: =E40-H40 -> 15
D41: DMS001 | E41: 10 | F41: 15000 | G41: =E41*F41 -> 150000 | I41: =E41-H41 -> 10
D42: VANILA01 | E42: 10 | F42: 13000 | G42: =E42*F42 -> 130000 | I42: =E42-H42 -> 10
D43: OOO1 | E43: 10 | F43: 18000 | G43: =E43*F43 -> 180000 | I43: =E43-H43 -> 10
D44: D002 | E44: 7 | F44: 13000 | G44: =E44*F44 -> 91000 | I44: =E44-H44 -> 7
D45: DMS002 | E45: 6 | F45: 25000 | G45: =E45*F45 -> 150000 | I45: =E45-H45 -> 6
...

Sheet laporan sanama mei
M2: menu utama | N2: 1000
B3: No | C3: Hari/ Tanggal | D3: List menu | E3: Jumlah | F3: Harga | G3: Total | H3: Refund | I3: Pemasukan | J3: Total Menu Terjual | M3: ekstra | N3: 500
B4: 1. | C4: 01 - 03 Mei 2025 | D4: MTG AYM | E4: 17 | I4: =E4-H4 -> 17 | J4: =SUM(I4:I21) -> 123 | P4: Tgl | Q4: Menu Utama | R4: Ekstra | S4: Total | U4: Laporan Per 1 Minggu
D5: AYM006 | E5: 15 | I5: =E5-H5 -> 15 | P5: 01 - 03 Mei 2025 | Q5: =N2*J4 -> 123000 | S5: =SUM(Q5:R5) -> 123000 | U5: 01 - 06 Mei 2025 | V5: =sum(S5:S6) -> 318000
D6: AYM SE | E6: 13 | I6: =E6-H6 -> 13 | P6: 04 - 06 Mei 2025 | Q6: =N2*J22 -> 195000 | S6: =SUM(Q6:R6) -> 195000 | U6: 07 - 11 Mei 2025 | V6: =S7 -> 230000
D7: D009 | E7: 11 | I7: =E7-H7 -> 11 | P7: 07 - 11 Mei 2025 | Q7: =N2*J42 -> 230000 | S7: =SUM(Q7:R7) -> 230000 | U7: 12 - 18 Mei 2025 | V7: =S8 -> 363000
D8: VANILA01 | E8: 10 | I8: =E8-H8 -> 10 | P8: 12 - 18 Mei 2025 | Q8: =N2*J63 -> 363000 | S8: =SUM(Q8:R8) -> 363000 | U8: 19 - 24 Mei 2025 | V8: =sum(S9:S10) -> 226000
D9: TKW01 | E9: 8 | I9: =E9-H9 -> 8 | P9: 19 - 21 Mei 2025 | Q9: =N2*J83 -> 123000 | S9: =SUM(Q9:R9) -> 123000 | U9: 25 - 31 Mei 2025 | V9: =sum(S11:S12) -> 190000
D10: D012 | E10: 8 | I10: =E10-H10 -> 8 | P10: 22 - 24 Mei 2025 | Q10: =N2*J103 -> 103000 | S10: =SUM(Q10:R10) -> 103000
D11: Event0021 | E11: 8 | I11: =E11-H11 -> 8 | P11: 25 - 27 Mei 2025 | Q11: =N2*J119 -> 76000 | S11: =SUM(Q11:R11) -> 76000
D12: NSAYAM005 | E12: 8 | I12: =E12-H12 -> 8 | P12: 28 - 31 Mei 2025 | Q12: =N2*J132 -> 114000 | S12: =SUM(Q12:R12) -> 114000
D13: D002 | E13: 6 | I13: =E13-H13 -> 6
D14: D018 | E14: 5 | I14: =E14-H14 -> 5
D15: DMS002 | E15: 3 | I15: =E15-H15 -> 3
D16: SMBL M | E16: 3 | I16: =E16-H16 -> 3 | P16: Total Keseluruhan | Q16: =sum(V5:V9) -> 1327000
D17: DMS001 | E17: 3 | I17: =E17-H17 -> 3
D18: bangladesh | E18: 2 | I18: =E18-H18 -> 2
D19: DG01 | E19: 1 | I19: =E19-H19 -> 1
D20: D004 | E20: 1 | I20: =E20-H20 -> 1
D21: LEMONTEA | E21: 1 | I21: =E21-H21 -> 1
B22: 2. | C22: 04 - 06 Mei 2025 | D22: AYM006 | E22: 32 | I22: =E22-H22 -> 32 | J22: =SUM(I22:I41) -> 195
D23: AYM SE | E23: 24 | I23: =E23-H23 -> 24
D24: MTG AYM | E24: 18 | H24: 1 | I24: =E24-H24 -> 17
D25: Event0021 | E25: 16 | I25: =E25-H25 -> 16
D26: NSAYAM005 | E26: 16 | I26: =E26-H26 -> 16
D27: D018 | E27: 14 | I27: =E27-H27 -> 14
D28: D012 | E28: 13 | I28: =E28-H28 -> 13
D29: D002 | E29: 10 | I29: =E29-H29 -> 10
D30: D009 | E30: 7 | I30: =E30-H30 -> 7
D31: LEMONTEA | E31: 7 | I31: =E31-H31 -> 7
D32: D004 | E32: 6 | I32: =E32-H32 -> 6
D33: DMS001 | E33: 6 | I33: =E33-H33 -> 6
D34: SMBL M | E34: 6 | I34: =E34-H34 -> 6
D35: bangladesh | E35: 5 | I35: =E35-H35 -> 5
D36: TBK22 | E36: 4 | I36: =E36-H36 -> 4
... D41: D006 | E41: 1 | I41: =E41-H41 -> 1
B42: 3. | C42: 07 - 11 Mei 2025 | D42: MTG AYM | E42: 40 | I42: =E42-H42 -> 40 | J42: =SUM(I42:I62) -> 230
D43: AYM006 | E43: 35 | I43: =E43-H43 -> 35
D44: AYM SE | E44: 36 | I44: =E44-H44 -> 36
D45: D002 | E45: 21 | I45: =E45-H45 -> 21
...

Sheet laporan sanama juni
M1: menu utama | N1: 1000
M2: ekstra | N2: 500
B3: No | C3: Hari/ Tanggal | D3: List menu | E3: Jumlah | F3: Harga | G3: Total | H3: Refund | I3: Pemasukan | J3: Total Menu Terjual | K3: Menu Ekstra | L3: Jumlah | M3: Total Ekstra | U3: Laporan per 1 Minggu
B4: 1. | C4: 01 - 03 Juni 2025 | D4: AYM SE | E4: 13 | I4: =E4-H4 -> 13 | J4: =SUM(I4:I18) -> 84 | K4: TELUR | L4: 2 | M4: =SUM(L4:L18) -> 2 | P4: Tgl | Q4: Menu Utama | R4: Ekstra | S4: Total | U4: 01 - 06 Juni 2025 | V4: =sum(S5:S6) -> 180500
D5: NSAYAM005 | E5: 9 | I5: =E5-H5 -> 9 | P5: 01 - 03 Juni 2025 | Q5: =N1*J4 -> 84000 | R5: =N2*M4 -> 1000 | S5: =sum(Q5:R5) -> 85000 | U5: 07 - 13 Juni 2025 | V5: =sum(S7:S8) -> 252500
D6: MTG AYM | E6: 9 | I6: =E6-H6 -> 9 | P6: 04 - 06 Juni 2025 | Q6: =N1*J19 -> 93000 | R6: =N2*M19 -> 2500 | S6: =sum(Q6:R6) -> 95500
D7: LEMONTEA | E7: 8 | I7: =E7-H7 -> 8 | P7: 07 - 09 Juni 2025 | Q7: =N1*J36 -> 72000 | R7: =N2*M36 -> 2500 | S7: =sum(Q7:R7) -> 74500
D8: bangladehs | E8: 7 | I8: =E8-H8 -> 7 | P8: 10 - 13 Juni 2025 | Q8: =N1*J54 -> 171000 | R8: =N2*M54 -> 7000 | S8: =sum(Q8:R8) -> 178000
D9: AYM006 | E9: 7 | I9: =E9-H9 -> 7
D10: TKW01 | E10: 6 | I10: =E10-H10 -> 6
D11: D018 | E11: 5 | I11: =E11-H11 -> 5
D12: Event0021 | E12: 5 | I12: =E12-H12 -> 5
D13: D002 | E13: 4 | I13: =E13-H13 -> 4
D14: DMS002 | E14: 3 | I14: =E14-H14 -> 3
D15: DG01 | E15: 3 | I15: =E15-H15 -> 3
D16: SMBL M | E16: 2 | I16: =E16-H16 -> 2
D17: D006 | E17: 2 | I17: =E17-H17 -> 2
D18: DMS001 | E18: 1 | I18: =E18-H18 -> 1
B19: 2. | C19: 04 - 06 Juni 2025 | D19: AYM SE | E19: 17 | I19: =E19-H19 -> 17 | J19: =SUM(I19:I35) -> 93 | K19: TELUR | L19: 5 | M19: =SUM(L19:L35) -> 5
D20: D002 | E20: 13 | I20: =E20-H20 -> 13
D21: bangladehs | E21: 9 | I21: =E21-H21 -> 9
D22: MTG AYM | E22: 8 | I22: =E22-H22 -> 8
D23: AYM006 | E23: 7 | I23: =E23-H23 -> 7
D24: NSAYAM005 | E24: 7 | I24: =E24-H24 -> 7
D25: Event0021 | E25: 6 | I25: =E25-H25 -> 6
D26: D018 | E26: 5 | I26: =E26-H26 -> 5
D27: D012 | E27: 4 | I27: =E27-H27 -> 4
D28: D006 | E28: 4 | I28: =E28-H28 -> 4
D29: TBK22 | E29: 3 | I29: =E29-H29 -> 3
D30: LEMONTEA | E30: 3 | I30: =E30-H30 -> 3
D31: DG01 | E31: 2 | I31: =E31-H31 -> 2
... D35: DMS003 | E35: 1 | I35: =E35-H35 -> 1
B36: 3. | C36: 07 - 09 Juni 2025 | D36: AYM SE | E36: 8 | I36: =E36-H36 -> 8 | J36: =SUM(I36:I53) -> 72 | K36: TELUR | L36: 4 | M36: =SUM(L36:L53) -> 5
D37: AYM006 | E37: 8 | I37: =E37-H37 -> 8 | K37: DAGING | L37: 1
D38: NSAYAM005 | E38: 8 | I38: =E38-H38 -> 8
D39: D012 | E39: 7 | I39: =E39-H39 -> 7
D40: MTG AYM | E40: 6 | I40: =E40-H40 -> 6
D41: D002 | E41: 6 | I41: =E41-H41 -> 6
D42: DG01 | E42: 5 | I42: =E42-H42 -> 5
D43: D018 | E43: 3 | I43: =E43-H43 -> 3
...
